2023-03-04 12:45:42,775 - log_exception.log_exception - ERROR - OSError: :There is an error while writing the dataframe to the Excel file operation in run_fed_scraping method while saving the fed_data dataframe to excel: :[Errno 13] Permission denied: '../Scraped_Data/fed_SpeechData.xlsx'.
2023-03-04 12:45:42,775 - log_exception.log_exception - ERROR - OSError: :There is an error while writing the dataframe to the Excel file operation in run_fed_scraping method while saving the fed_data dataframe to excel: :[Errno 13] Permission denied: '../Scraped_Data/fed_SpeechData.xlsx'.
2023-03-04 12:45:42,775 - log_exception.log_exception - ERROR - OSError: :There is an error while writing the dataframe to the Excel file operation in run_fed_scraping method while saving the fed_data dataframe to excel: :[Errno 13] Permission denied: '../Scraped_Data/fed_SpeechData.xlsx'.
2023-03-04 16:22:34,515 - log_exception.log_exception - ERROR - OSError: : Could not open/read file in download_csv in Ecb_csv_Download.py file ('Connection broken: IncompleteRead(198 bytes read, 314 more expected)', IncompleteRead(198 bytes read, 314 more expected))
2023-03-04 16:22:34,515 - log_exception.log_exception - ERROR - OSError: : Could not open/read file in download_csv in Ecb_csv_Download.py file ('Connection broken: IncompleteRead(198 bytes read, 314 more expected)', IncompleteRead(198 bytes read, 314 more expected))
2023-03-04 17:02:20,745 - log_exception.log_exception - ERROR - RuntimeError: :An error has occurred while loading the checkpoint file. Please try again load_model method in prediction.py . [enforce fail at C:\actions-runner\_work\pytorch\pytorch\builder\windows\pytorch\c10\core\impl\alloc_cpu.cpp:72] data. DefaultCPUAllocator: not enough memory: you tried to allocate 4194304 bytes.
2023-03-04 17:02:20,745 - log_exception.log_exception - ERROR - RuntimeError: :An error has occurred while loading the checkpoint file. Please try again load_model method in prediction.py . [enforce fail at C:\actions-runner\_work\pytorch\pytorch\builder\windows\pytorch\c10\core\impl\alloc_cpu.cpp:72] data. DefaultCPUAllocator: not enough memory: you tried to allocate 4194304 bytes.
2023-03-04 17:02:23,802 - log_exception.log_exception - ERROR - AttributeError: :fed_data DataFrame does not have the required attribute, in summary_prediction method in Fed_summary_prediction file.py while saving the fed_data dataframe to excel: :'NoneType' object has no attribute 'model'.
2023-03-04 17:02:23,802 - log_exception.log_exception - ERROR - AttributeError: :fed_data DataFrame does not have the required attribute, in summary_prediction method in Fed_summary_prediction file.py while saving the fed_data dataframe to excel: :'NoneType' object has no attribute 'model'.
2023-03-04 17:32:13,755 - log_exception.log_exception - ERROR - The "quotes" column does not exist in the input data in clean_summary method of cleaning_summary.py file 
2023-03-04 17:32:13,755 - log_exception.log_exception - ERROR - The "quotes" column does not exist in the input data in clean_summary method of cleaning_summary.py file 
2023-03-04 17:32:13,755 - log_exception.log_exception - ERROR - The "quotes" column does not exist in the input data in clean_summary method of cleaning_summary.py file 
2023-03-04 17:35:42,612 - log_exception.log_exception - ERROR - The "quotes" column does not exist in the input data in clean_summary method of cleaning_summary.py file 
2023-03-04 17:35:42,612 - log_exception.log_exception - ERROR - The "quotes" column does not exist in the input data in clean_summary method of cleaning_summary.py file 
2023-03-04 17:35:42,612 - log_exception.log_exception - ERROR - The "quotes" column does not exist in the input data in clean_summary method of cleaning_summary.py file 
2023-03-04 18:03:59,819 - log_exception.log_exception - ERROR - OSError: :There is an error while writing the dataframe to the Excel file operation in summary_prediction method in Fed_summary_prediction file.py while saving the fed_data dataframe to excel: :[Errno 2] No such file or directory: '../summary_prediction/ALL_FED_SPEECH_SUMMARY_DAT.xlsx'.
2023-03-04 20:18:18,543 - log_exception.log_exception - ERROR - FileNotFoundError: : Unable find file to read in word_cloud method in word_cloud.py [Errno 2] No such file or directory: 'test_file_not_found_error.xlsx'
2023-03-04 20:18:19,253 - log_exception.log_exception - ERROR - KeyError: :  one or more of the specified keys ("date", "quotes", or "speaker") do not exist in the self.data dictionary in word_cloud method in word_cloud.py 'date'
2023-03-04 20:25:13,342 - log_exception.log_exception - ERROR - FileNotFoundError: : Unable find file to read in word_cloud method in word_cloud.py [Errno 2] No such file or directory: 'test_file_not_found_error.xlsx'
2023-03-04 20:25:14,088 - log_exception.log_exception - ERROR - KeyError: :  one or more of the specified keys ("date", "quotes", or "speaker") do not exist in the self.data dictionary in word_cloud method in word_cloud.py 'date'
2023-03-04 20:29:36,621 - log_exception.log_exception - ERROR - FileNotFoundError: : Unable find file to read in word_cloud method in word_cloud.py [Errno 2] No such file or directory: 'test_file_not_found_error.xlsx'
2023-03-04 20:29:37,323 - log_exception.log_exception - ERROR - KeyError: :  one or more of the specified keys ("date", "quotes", or "speaker") do not exist in the self.data dictionary in word_cloud method in word_cloud.py 'date'
